2025-06-27 06:19:42,205 ERROR scheduler Exception in Enqueue Events for Site apple.local
Traceback (most recent call last):
  File "/home/tridotstech/frappe-training/env/lib/python3.11/site-packages/pymysql/connections.py", line 649, in connect
    sock = socket.create_connection(
           ^^^^^^^^^^^^^^^^^^^^^^^^^
  File "/usr/lib/python3.11/socket.py", line 863, in create_connection
    raise exceptions[0]
  File "/usr/lib/python3.11/socket.py", line 848, in create_connection
    sock.connect(sa)
ConnectionRefusedError: [Errno 111] Connection refused

During handling of the above exception, another exception occurred:

Traceback (most recent call last):
  File "/home/tridotstech/frappe-training/apps/frappe/frappe/utils/scheduler.py", line 99, in enqueue_events_for_site
    if is_scheduler_inactive():
       ^^^^^^^^^^^^^^^^^^^^^^^
  File "/home/tridotstech/frappe-training/apps/frappe/frappe/utils/scheduler.py", line 143, in is_scheduler_inactive
    if is_scheduler_disabled(verbose=verbose):
       ^^^^^^^^^^^^^^^^^^^^^^^^^^^^^^^^^^^^^^
  File "/home/tridotstech/frappe-training/apps/frappe/frappe/utils/scheduler.py", line 156, in is_scheduler_disabled
    frappe.db.get_single_value("System Settings", "enable_scheduler")
  File "/home/tridotstech/frappe-training/apps/frappe/frappe/database/database.py", line 837, in get_single_value
    ).run()
      ^^^^^
  File "/home/tridotstech/frappe-training/apps/frappe/frappe/query_builder/utils.py", line 87, in execute_query
    result = frappe.db.sql(query, params, *args, **kwargs)  # nosemgrep
             ^^^^^^^^^^^^^^^^^^^^^^^^^^^^^^^^^^^^^^^^^^^^^
  File "/home/tridotstech/frappe-training/apps/frappe/frappe/database/database.py", line 207, in sql
    self.connect()
  File "/home/tridotstech/frappe-training/apps/frappe/frappe/database/database.py", line 112, in connect
    self._conn: "MariadbConnection" | "PostgresConnection" = self.get_connection()
                                                             ^^^^^^^^^^^^^^^^^^^^^
  File "/home/tridotstech/frappe-training/apps/frappe/frappe/database/mariadb/database.py", line 108, in get_connection
    conn = self._get_connection()
           ^^^^^^^^^^^^^^^^^^^^^^
  File "/home/tridotstech/frappe-training/apps/frappe/frappe/database/mariadb/database.py", line 114, in _get_connection
    return self.create_connection()
           ^^^^^^^^^^^^^^^^^^^^^^^^
  File "/home/tridotstech/frappe-training/apps/frappe/frappe/database/mariadb/database.py", line 117, in create_connection
    return pymysql.connect(**self.get_connection_settings())
           ^^^^^^^^^^^^^^^^^^^^^^^^^^^^^^^^^^^^^^^^^^^^^^^^^
  File "/home/tridotstech/frappe-training/env/lib/python3.11/site-packages/pymysql/connections.py", line 361, in __init__
    self.connect()
  File "/home/tridotstech/frappe-training/env/lib/python3.11/site-packages/pymysql/connections.py", line 716, in connect
    raise exc
pymysql.err.OperationalError: (2003, "Can't connect to MySQL server on '127.0.0.1' ([Errno 111] Connection refused)")
2025-06-27 06:20:54,635 ERROR scheduler Exception in Enqueue Events for Site apple.local
Traceback (most recent call last):
  File "/home/tridotstech/frappe-training/env/lib/python3.11/site-packages/pymysql/connections.py", line 649, in connect
    sock = socket.create_connection(
           ^^^^^^^^^^^^^^^^^^^^^^^^^
  File "/usr/lib/python3.11/socket.py", line 863, in create_connection
    raise exceptions[0]
  File "/usr/lib/python3.11/socket.py", line 848, in create_connection
    sock.connect(sa)
ConnectionRefusedError: [Errno 111] Connection refused

During handling of the above exception, another exception occurred:

Traceback (most recent call last):
  File "/home/tridotstech/frappe-training/apps/frappe/frappe/utils/scheduler.py", line 99, in enqueue_events_for_site
    if is_scheduler_inactive():
       ^^^^^^^^^^^^^^^^^^^^^^^
  File "/home/tridotstech/frappe-training/apps/frappe/frappe/utils/scheduler.py", line 143, in is_scheduler_inactive
    if is_scheduler_disabled(verbose=verbose):
       ^^^^^^^^^^^^^^^^^^^^^^^^^^^^^^^^^^^^^^
  File "/home/tridotstech/frappe-training/apps/frappe/frappe/utils/scheduler.py", line 156, in is_scheduler_disabled
    frappe.db.get_single_value("System Settings", "enable_scheduler")
  File "/home/tridotstech/frappe-training/apps/frappe/frappe/database/database.py", line 837, in get_single_value
    ).run()
      ^^^^^
  File "/home/tridotstech/frappe-training/apps/frappe/frappe/query_builder/utils.py", line 87, in execute_query
    result = frappe.db.sql(query, params, *args, **kwargs)  # nosemgrep
             ^^^^^^^^^^^^^^^^^^^^^^^^^^^^^^^^^^^^^^^^^^^^^
  File "/home/tridotstech/frappe-training/apps/frappe/frappe/database/database.py", line 207, in sql
    self.connect()
  File "/home/tridotstech/frappe-training/apps/frappe/frappe/database/database.py", line 112, in connect
    self._conn: "MariadbConnection" | "PostgresConnection" = self.get_connection()
                                                             ^^^^^^^^^^^^^^^^^^^^^
  File "/home/tridotstech/frappe-training/apps/frappe/frappe/database/mariadb/database.py", line 108, in get_connection
    conn = self._get_connection()
           ^^^^^^^^^^^^^^^^^^^^^^
  File "/home/tridotstech/frappe-training/apps/frappe/frappe/database/mariadb/database.py", line 114, in _get_connection
    return self.create_connection()
           ^^^^^^^^^^^^^^^^^^^^^^^^
  File "/home/tridotstech/frappe-training/apps/frappe/frappe/database/mariadb/database.py", line 117, in create_connection
    return pymysql.connect(**self.get_connection_settings())
           ^^^^^^^^^^^^^^^^^^^^^^^^^^^^^^^^^^^^^^^^^^^^^^^^^
  File "/home/tridotstech/frappe-training/env/lib/python3.11/site-packages/pymysql/connections.py", line 361, in __init__
    self.connect()
  File "/home/tridotstech/frappe-training/env/lib/python3.11/site-packages/pymysql/connections.py", line 716, in connect
    raise exc
pymysql.err.OperationalError: (2003, "Can't connect to MySQL server on '127.0.0.1' ([Errno 111] Connection refused)")
2025-06-27 06:21:54,646 ERROR scheduler Exception in Enqueue Events for Site apple.local
Traceback (most recent call last):
  File "/home/tridotstech/frappe-training/env/lib/python3.11/site-packages/pymysql/connections.py", line 649, in connect
    sock = socket.create_connection(
           ^^^^^^^^^^^^^^^^^^^^^^^^^
  File "/usr/lib/python3.11/socket.py", line 863, in create_connection
    raise exceptions[0]
  File "/usr/lib/python3.11/socket.py", line 848, in create_connection
    sock.connect(sa)
ConnectionRefusedError: [Errno 111] Connection refused

During handling of the above exception, another exception occurred:

Traceback (most recent call last):
  File "/home/tridotstech/frappe-training/apps/frappe/frappe/utils/scheduler.py", line 99, in enqueue_events_for_site
    if is_scheduler_inactive():
       ^^^^^^^^^^^^^^^^^^^^^^^
  File "/home/tridotstech/frappe-training/apps/frappe/frappe/utils/scheduler.py", line 143, in is_scheduler_inactive
    if is_scheduler_disabled(verbose=verbose):
       ^^^^^^^^^^^^^^^^^^^^^^^^^^^^^^^^^^^^^^
  File "/home/tridotstech/frappe-training/apps/frappe/frappe/utils/scheduler.py", line 156, in is_scheduler_disabled
    frappe.db.get_single_value("System Settings", "enable_scheduler")
  File "/home/tridotstech/frappe-training/apps/frappe/frappe/database/database.py", line 837, in get_single_value
    ).run()
      ^^^^^
  File "/home/tridotstech/frappe-training/apps/frappe/frappe/query_builder/utils.py", line 87, in execute_query
    result = frappe.db.sql(query, params, *args, **kwargs)  # nosemgrep
             ^^^^^^^^^^^^^^^^^^^^^^^^^^^^^^^^^^^^^^^^^^^^^
  File "/home/tridotstech/frappe-training/apps/frappe/frappe/database/database.py", line 207, in sql
    self.connect()
  File "/home/tridotstech/frappe-training/apps/frappe/frappe/database/database.py", line 112, in connect
    self._conn: "MariadbConnection" | "PostgresConnection" = self.get_connection()
                                                             ^^^^^^^^^^^^^^^^^^^^^
  File "/home/tridotstech/frappe-training/apps/frappe/frappe/database/mariadb/database.py", line 108, in get_connection
    conn = self._get_connection()
           ^^^^^^^^^^^^^^^^^^^^^^
  File "/home/tridotstech/frappe-training/apps/frappe/frappe/database/mariadb/database.py", line 114, in _get_connection
    return self.create_connection()
           ^^^^^^^^^^^^^^^^^^^^^^^^
  File "/home/tridotstech/frappe-training/apps/frappe/frappe/database/mariadb/database.py", line 117, in create_connection
    return pymysql.connect(**self.get_connection_settings())
           ^^^^^^^^^^^^^^^^^^^^^^^^^^^^^^^^^^^^^^^^^^^^^^^^^
  File "/home/tridotstech/frappe-training/env/lib/python3.11/site-packages/pymysql/connections.py", line 361, in __init__
    self.connect()
  File "/home/tridotstech/frappe-training/env/lib/python3.11/site-packages/pymysql/connections.py", line 716, in connect
    raise exc
pymysql.err.OperationalError: (2003, "Can't connect to MySQL server on '127.0.0.1' ([Errno 111] Connection refused)")
2025-06-27 06:22:54,681 ERROR scheduler Exception in Enqueue Events for Site apple.local
Traceback (most recent call last):
  File "/home/tridotstech/frappe-training/env/lib/python3.11/site-packages/pymysql/connections.py", line 649, in connect
    sock = socket.create_connection(
           ^^^^^^^^^^^^^^^^^^^^^^^^^
  File "/usr/lib/python3.11/socket.py", line 863, in create_connection
    raise exceptions[0]
  File "/usr/lib/python3.11/socket.py", line 848, in create_connection
    sock.connect(sa)
ConnectionRefusedError: [Errno 111] Connection refused

During handling of the above exception, another exception occurred:

Traceback (most recent call last):
  File "/home/tridotstech/frappe-training/apps/frappe/frappe/utils/scheduler.py", line 99, in enqueue_events_for_site
    if is_scheduler_inactive():
       ^^^^^^^^^^^^^^^^^^^^^^^
  File "/home/tridotstech/frappe-training/apps/frappe/frappe/utils/scheduler.py", line 143, in is_scheduler_inactive
    if is_scheduler_disabled(verbose=verbose):
       ^^^^^^^^^^^^^^^^^^^^^^^^^^^^^^^^^^^^^^
  File "/home/tridotstech/frappe-training/apps/frappe/frappe/utils/scheduler.py", line 156, in is_scheduler_disabled
    frappe.db.get_single_value("System Settings", "enable_scheduler")
  File "/home/tridotstech/frappe-training/apps/frappe/frappe/database/database.py", line 837, in get_single_value
    ).run()
      ^^^^^
  File "/home/tridotstech/frappe-training/apps/frappe/frappe/query_builder/utils.py", line 87, in execute_query
    result = frappe.db.sql(query, params, *args, **kwargs)  # nosemgrep
             ^^^^^^^^^^^^^^^^^^^^^^^^^^^^^^^^^^^^^^^^^^^^^
  File "/home/tridotstech/frappe-training/apps/frappe/frappe/database/database.py", line 207, in sql
    self.connect()
  File "/home/tridotstech/frappe-training/apps/frappe/frappe/database/database.py", line 112, in connect
    self._conn: "MariadbConnection" | "PostgresConnection" = self.get_connection()
                                                             ^^^^^^^^^^^^^^^^^^^^^
  File "/home/tridotstech/frappe-training/apps/frappe/frappe/database/mariadb/database.py", line 108, in get_connection
    conn = self._get_connection()
           ^^^^^^^^^^^^^^^^^^^^^^
  File "/home/tridotstech/frappe-training/apps/frappe/frappe/database/mariadb/database.py", line 114, in _get_connection
    return self.create_connection()
           ^^^^^^^^^^^^^^^^^^^^^^^^
  File "/home/tridotstech/frappe-training/apps/frappe/frappe/database/mariadb/database.py", line 117, in create_connection
    return pymysql.connect(**self.get_connection_settings())
           ^^^^^^^^^^^^^^^^^^^^^^^^^^^^^^^^^^^^^^^^^^^^^^^^^
  File "/home/tridotstech/frappe-training/env/lib/python3.11/site-packages/pymysql/connections.py", line 361, in __init__
    self.connect()
  File "/home/tridotstech/frappe-training/env/lib/python3.11/site-packages/pymysql/connections.py", line 716, in connect
    raise exc
pymysql.err.OperationalError: (2003, "Can't connect to MySQL server on '127.0.0.1' ([Errno 111] Connection refused)")
2025-06-27 06:23:54,704 ERROR scheduler Exception in Enqueue Events for Site apple.local
Traceback (most recent call last):
  File "/home/tridotstech/frappe-training/env/lib/python3.11/site-packages/pymysql/connections.py", line 649, in connect
    sock = socket.create_connection(
           ^^^^^^^^^^^^^^^^^^^^^^^^^
  File "/usr/lib/python3.11/socket.py", line 863, in create_connection
    raise exceptions[0]
  File "/usr/lib/python3.11/socket.py", line 848, in create_connection
    sock.connect(sa)
ConnectionRefusedError: [Errno 111] Connection refused

During handling of the above exception, another exception occurred:

Traceback (most recent call last):
  File "/home/tridotstech/frappe-training/apps/frappe/frappe/utils/scheduler.py", line 99, in enqueue_events_for_site
    if is_scheduler_inactive():
       ^^^^^^^^^^^^^^^^^^^^^^^
  File "/home/tridotstech/frappe-training/apps/frappe/frappe/utils/scheduler.py", line 143, in is_scheduler_inactive
    if is_scheduler_disabled(verbose=verbose):
       ^^^^^^^^^^^^^^^^^^^^^^^^^^^^^^^^^^^^^^
  File "/home/tridotstech/frappe-training/apps/frappe/frappe/utils/scheduler.py", line 156, in is_scheduler_disabled
    frappe.db.get_single_value("System Settings", "enable_scheduler")
  File "/home/tridotstech/frappe-training/apps/frappe/frappe/database/database.py", line 837, in get_single_value
    ).run()
      ^^^^^
  File "/home/tridotstech/frappe-training/apps/frappe/frappe/query_builder/utils.py", line 87, in execute_query
    result = frappe.db.sql(query, params, *args, **kwargs)  # nosemgrep
             ^^^^^^^^^^^^^^^^^^^^^^^^^^^^^^^^^^^^^^^^^^^^^
  File "/home/tridotstech/frappe-training/apps/frappe/frappe/database/database.py", line 207, in sql
    self.connect()
  File "/home/tridotstech/frappe-training/apps/frappe/frappe/database/database.py", line 112, in connect
    self._conn: "MariadbConnection" | "PostgresConnection" = self.get_connection()
                                                             ^^^^^^^^^^^^^^^^^^^^^
  File "/home/tridotstech/frappe-training/apps/frappe/frappe/database/mariadb/database.py", line 108, in get_connection
    conn = self._get_connection()
           ^^^^^^^^^^^^^^^^^^^^^^
  File "/home/tridotstech/frappe-training/apps/frappe/frappe/database/mariadb/database.py", line 114, in _get_connection
    return self.create_connection()
           ^^^^^^^^^^^^^^^^^^^^^^^^
  File "/home/tridotstech/frappe-training/apps/frappe/frappe/database/mariadb/database.py", line 117, in create_connection
    return pymysql.connect(**self.get_connection_settings())
           ^^^^^^^^^^^^^^^^^^^^^^^^^^^^^^^^^^^^^^^^^^^^^^^^^
  File "/home/tridotstech/frappe-training/env/lib/python3.11/site-packages/pymysql/connections.py", line 361, in __init__
    self.connect()
  File "/home/tridotstech/frappe-training/env/lib/python3.11/site-packages/pymysql/connections.py", line 716, in connect
    raise exc
pymysql.err.OperationalError: (2003, "Can't connect to MySQL server on '127.0.0.1' ([Errno 111] Connection refused)")
2025-06-27 06:24:54,716 ERROR scheduler Exception in Enqueue Events for Site apple.local
Traceback (most recent call last):
  File "/home/tridotstech/frappe-training/env/lib/python3.11/site-packages/pymysql/connections.py", line 649, in connect
    sock = socket.create_connection(
           ^^^^^^^^^^^^^^^^^^^^^^^^^
  File "/usr/lib/python3.11/socket.py", line 863, in create_connection
    raise exceptions[0]
  File "/usr/lib/python3.11/socket.py", line 848, in create_connection
    sock.connect(sa)
ConnectionRefusedError: [Errno 111] Connection refused

During handling of the above exception, another exception occurred:

Traceback (most recent call last):
  File "/home/tridotstech/frappe-training/apps/frappe/frappe/utils/scheduler.py", line 99, in enqueue_events_for_site
    if is_scheduler_inactive():
       ^^^^^^^^^^^^^^^^^^^^^^^
  File "/home/tridotstech/frappe-training/apps/frappe/frappe/utils/scheduler.py", line 143, in is_scheduler_inactive
    if is_scheduler_disabled(verbose=verbose):
       ^^^^^^^^^^^^^^^^^^^^^^^^^^^^^^^^^^^^^^
  File "/home/tridotstech/frappe-training/apps/frappe/frappe/utils/scheduler.py", line 156, in is_scheduler_disabled
    frappe.db.get_single_value("System Settings", "enable_scheduler")
  File "/home/tridotstech/frappe-training/apps/frappe/frappe/database/database.py", line 837, in get_single_value
    ).run()
      ^^^^^
  File "/home/tridotstech/frappe-training/apps/frappe/frappe/query_builder/utils.py", line 87, in execute_query
    result = frappe.db.sql(query, params, *args, **kwargs)  # nosemgrep
             ^^^^^^^^^^^^^^^^^^^^^^^^^^^^^^^^^^^^^^^^^^^^^
  File "/home/tridotstech/frappe-training/apps/frappe/frappe/database/database.py", line 207, in sql
    self.connect()
  File "/home/tridotstech/frappe-training/apps/frappe/frappe/database/database.py", line 112, in connect
    self._conn: "MariadbConnection" | "PostgresConnection" = self.get_connection()
                                                             ^^^^^^^^^^^^^^^^^^^^^
  File "/home/tridotstech/frappe-training/apps/frappe/frappe/database/mariadb/database.py", line 108, in get_connection
    conn = self._get_connection()
           ^^^^^^^^^^^^^^^^^^^^^^
  File "/home/tridotstech/frappe-training/apps/frappe/frappe/database/mariadb/database.py", line 114, in _get_connection
    return self.create_connection()
           ^^^^^^^^^^^^^^^^^^^^^^^^
  File "/home/tridotstech/frappe-training/apps/frappe/frappe/database/mariadb/database.py", line 117, in create_connection
    return pymysql.connect(**self.get_connection_settings())
           ^^^^^^^^^^^^^^^^^^^^^^^^^^^^^^^^^^^^^^^^^^^^^^^^^
  File "/home/tridotstech/frappe-training/env/lib/python3.11/site-packages/pymysql/connections.py", line 361, in __init__
    self.connect()
  File "/home/tridotstech/frappe-training/env/lib/python3.11/site-packages/pymysql/connections.py", line 716, in connect
    raise exc
pymysql.err.OperationalError: (2003, "Can't connect to MySQL server on '127.0.0.1' ([Errno 111] Connection refused)")
2025-06-28 06:39:17,038 ERROR scheduler Exception in Enqueue Events for Site apple.local
Traceback (most recent call last):
  File "/home/tridotstech/frappe-training/env/lib/python3.11/site-packages/pymysql/connections.py", line 649, in connect
    sock = socket.create_connection(
           ^^^^^^^^^^^^^^^^^^^^^^^^^
  File "/usr/lib/python3.11/socket.py", line 863, in create_connection
    raise exceptions[0]
  File "/usr/lib/python3.11/socket.py", line 848, in create_connection
    sock.connect(sa)
ConnectionRefusedError: [Errno 111] Connection refused

During handling of the above exception, another exception occurred:

Traceback (most recent call last):
  File "/home/tridotstech/frappe-training/apps/frappe/frappe/utils/scheduler.py", line 99, in enqueue_events_for_site
    if is_scheduler_inactive():
       ^^^^^^^^^^^^^^^^^^^^^^^
  File "/home/tridotstech/frappe-training/apps/frappe/frappe/utils/scheduler.py", line 143, in is_scheduler_inactive
    if is_scheduler_disabled(verbose=verbose):
       ^^^^^^^^^^^^^^^^^^^^^^^^^^^^^^^^^^^^^^
  File "/home/tridotstech/frappe-training/apps/frappe/frappe/utils/scheduler.py", line 156, in is_scheduler_disabled
    frappe.db.get_single_value("System Settings", "enable_scheduler")
  File "/home/tridotstech/frappe-training/apps/frappe/frappe/database/database.py", line 837, in get_single_value
    ).run()
      ^^^^^
  File "/home/tridotstech/frappe-training/apps/frappe/frappe/query_builder/utils.py", line 87, in execute_query
    result = frappe.db.sql(query, params, *args, **kwargs)  # nosemgrep
             ^^^^^^^^^^^^^^^^^^^^^^^^^^^^^^^^^^^^^^^^^^^^^
  File "/home/tridotstech/frappe-training/apps/frappe/frappe/database/database.py", line 207, in sql
    self.connect()
  File "/home/tridotstech/frappe-training/apps/frappe/frappe/database/database.py", line 112, in connect
    self._conn: "MariadbConnection" | "PostgresConnection" = self.get_connection()
                                                             ^^^^^^^^^^^^^^^^^^^^^
  File "/home/tridotstech/frappe-training/apps/frappe/frappe/database/mariadb/database.py", line 108, in get_connection
    conn = self._get_connection()
           ^^^^^^^^^^^^^^^^^^^^^^
  File "/home/tridotstech/frappe-training/apps/frappe/frappe/database/mariadb/database.py", line 114, in _get_connection
    return self.create_connection()
           ^^^^^^^^^^^^^^^^^^^^^^^^
  File "/home/tridotstech/frappe-training/apps/frappe/frappe/database/mariadb/database.py", line 117, in create_connection
    return pymysql.connect(**self.get_connection_settings())
           ^^^^^^^^^^^^^^^^^^^^^^^^^^^^^^^^^^^^^^^^^^^^^^^^^
  File "/home/tridotstech/frappe-training/env/lib/python3.11/site-packages/pymysql/connections.py", line 361, in __init__
    self.connect()
  File "/home/tridotstech/frappe-training/env/lib/python3.11/site-packages/pymysql/connections.py", line 716, in connect
    raise exc
pymysql.err.OperationalError: (2003, "Can't connect to MySQL server on '127.0.0.1' ([Errno 111] Connection refused)")
2025-06-28 06:40:17,051 ERROR scheduler Exception in Enqueue Events for Site apple.local
Traceback (most recent call last):
  File "/home/tridotstech/frappe-training/env/lib/python3.11/site-packages/pymysql/connections.py", line 649, in connect
    sock = socket.create_connection(
           ^^^^^^^^^^^^^^^^^^^^^^^^^
  File "/usr/lib/python3.11/socket.py", line 863, in create_connection
    raise exceptions[0]
  File "/usr/lib/python3.11/socket.py", line 848, in create_connection
    sock.connect(sa)
ConnectionRefusedError: [Errno 111] Connection refused

During handling of the above exception, another exception occurred:

Traceback (most recent call last):
  File "/home/tridotstech/frappe-training/apps/frappe/frappe/utils/scheduler.py", line 99, in enqueue_events_for_site
    if is_scheduler_inactive():
       ^^^^^^^^^^^^^^^^^^^^^^^
  File "/home/tridotstech/frappe-training/apps/frappe/frappe/utils/scheduler.py", line 143, in is_scheduler_inactive
    if is_scheduler_disabled(verbose=verbose):
       ^^^^^^^^^^^^^^^^^^^^^^^^^^^^^^^^^^^^^^
  File "/home/tridotstech/frappe-training/apps/frappe/frappe/utils/scheduler.py", line 156, in is_scheduler_disabled
    frappe.db.get_single_value("System Settings", "enable_scheduler")
  File "/home/tridotstech/frappe-training/apps/frappe/frappe/database/database.py", line 837, in get_single_value
    ).run()
      ^^^^^
  File "/home/tridotstech/frappe-training/apps/frappe/frappe/query_builder/utils.py", line 87, in execute_query
    result = frappe.db.sql(query, params, *args, **kwargs)  # nosemgrep
             ^^^^^^^^^^^^^^^^^^^^^^^^^^^^^^^^^^^^^^^^^^^^^
  File "/home/tridotstech/frappe-training/apps/frappe/frappe/database/database.py", line 207, in sql
    self.connect()
  File "/home/tridotstech/frappe-training/apps/frappe/frappe/database/database.py", line 112, in connect
    self._conn: "MariadbConnection" | "PostgresConnection" = self.get_connection()
                                                             ^^^^^^^^^^^^^^^^^^^^^
  File "/home/tridotstech/frappe-training/apps/frappe/frappe/database/mariadb/database.py", line 108, in get_connection
    conn = self._get_connection()
           ^^^^^^^^^^^^^^^^^^^^^^
  File "/home/tridotstech/frappe-training/apps/frappe/frappe/database/mariadb/database.py", line 114, in _get_connection
    return self.create_connection()
           ^^^^^^^^^^^^^^^^^^^^^^^^
  File "/home/tridotstech/frappe-training/apps/frappe/frappe/database/mariadb/database.py", line 117, in create_connection
    return pymysql.connect(**self.get_connection_settings())
           ^^^^^^^^^^^^^^^^^^^^^^^^^^^^^^^^^^^^^^^^^^^^^^^^^
  File "/home/tridotstech/frappe-training/env/lib/python3.11/site-packages/pymysql/connections.py", line 361, in __init__
    self.connect()
  File "/home/tridotstech/frappe-training/env/lib/python3.11/site-packages/pymysql/connections.py", line 716, in connect
    raise exc
pymysql.err.OperationalError: (2003, "Can't connect to MySQL server on '127.0.0.1' ([Errno 111] Connection refused)")
2025-06-28 06:41:17,079 ERROR scheduler Exception in Enqueue Events for Site apple.local
Traceback (most recent call last):
  File "/home/tridotstech/frappe-training/env/lib/python3.11/site-packages/pymysql/connections.py", line 649, in connect
    sock = socket.create_connection(
           ^^^^^^^^^^^^^^^^^^^^^^^^^
  File "/usr/lib/python3.11/socket.py", line 863, in create_connection
    raise exceptions[0]
  File "/usr/lib/python3.11/socket.py", line 848, in create_connection
    sock.connect(sa)
ConnectionRefusedError: [Errno 111] Connection refused

During handling of the above exception, another exception occurred:

Traceback (most recent call last):
  File "/home/tridotstech/frappe-training/apps/frappe/frappe/utils/scheduler.py", line 99, in enqueue_events_for_site
    if is_scheduler_inactive():
       ^^^^^^^^^^^^^^^^^^^^^^^
  File "/home/tridotstech/frappe-training/apps/frappe/frappe/utils/scheduler.py", line 143, in is_scheduler_inactive
    if is_scheduler_disabled(verbose=verbose):
       ^^^^^^^^^^^^^^^^^^^^^^^^^^^^^^^^^^^^^^
  File "/home/tridotstech/frappe-training/apps/frappe/frappe/utils/scheduler.py", line 156, in is_scheduler_disabled
    frappe.db.get_single_value("System Settings", "enable_scheduler")
  File "/home/tridotstech/frappe-training/apps/frappe/frappe/database/database.py", line 837, in get_single_value
    ).run()
      ^^^^^
  File "/home/tridotstech/frappe-training/apps/frappe/frappe/query_builder/utils.py", line 87, in execute_query
    result = frappe.db.sql(query, params, *args, **kwargs)  # nosemgrep
             ^^^^^^^^^^^^^^^^^^^^^^^^^^^^^^^^^^^^^^^^^^^^^
  File "/home/tridotstech/frappe-training/apps/frappe/frappe/database/database.py", line 207, in sql
    self.connect()
  File "/home/tridotstech/frappe-training/apps/frappe/frappe/database/database.py", line 112, in connect
    self._conn: "MariadbConnection" | "PostgresConnection" = self.get_connection()
                                                             ^^^^^^^^^^^^^^^^^^^^^
  File "/home/tridotstech/frappe-training/apps/frappe/frappe/database/mariadb/database.py", line 108, in get_connection
    conn = self._get_connection()
           ^^^^^^^^^^^^^^^^^^^^^^
  File "/home/tridotstech/frappe-training/apps/frappe/frappe/database/mariadb/database.py", line 114, in _get_connection
    return self.create_connection()
           ^^^^^^^^^^^^^^^^^^^^^^^^
  File "/home/tridotstech/frappe-training/apps/frappe/frappe/database/mariadb/database.py", line 117, in create_connection
    return pymysql.connect(**self.get_connection_settings())
           ^^^^^^^^^^^^^^^^^^^^^^^^^^^^^^^^^^^^^^^^^^^^^^^^^
  File "/home/tridotstech/frappe-training/env/lib/python3.11/site-packages/pymysql/connections.py", line 361, in __init__
    self.connect()
  File "/home/tridotstech/frappe-training/env/lib/python3.11/site-packages/pymysql/connections.py", line 716, in connect
    raise exc
pymysql.err.OperationalError: (2003, "Can't connect to MySQL server on '127.0.0.1' ([Errno 111] Connection refused)")
2025-06-28 06:42:17,088 ERROR scheduler Exception in Enqueue Events for Site apple.local
Traceback (most recent call last):
  File "/home/tridotstech/frappe-training/env/lib/python3.11/site-packages/pymysql/connections.py", line 649, in connect
    sock = socket.create_connection(
           ^^^^^^^^^^^^^^^^^^^^^^^^^
  File "/usr/lib/python3.11/socket.py", line 863, in create_connection
    raise exceptions[0]
  File "/usr/lib/python3.11/socket.py", line 848, in create_connection
    sock.connect(sa)
ConnectionRefusedError: [Errno 111] Connection refused

During handling of the above exception, another exception occurred:

Traceback (most recent call last):
  File "/home/tridotstech/frappe-training/apps/frappe/frappe/utils/scheduler.py", line 99, in enqueue_events_for_site
    if is_scheduler_inactive():
       ^^^^^^^^^^^^^^^^^^^^^^^
  File "/home/tridotstech/frappe-training/apps/frappe/frappe/utils/scheduler.py", line 143, in is_scheduler_inactive
    if is_scheduler_disabled(verbose=verbose):
       ^^^^^^^^^^^^^^^^^^^^^^^^^^^^^^^^^^^^^^
  File "/home/tridotstech/frappe-training/apps/frappe/frappe/utils/scheduler.py", line 156, in is_scheduler_disabled
    frappe.db.get_single_value("System Settings", "enable_scheduler")
  File "/home/tridotstech/frappe-training/apps/frappe/frappe/database/database.py", line 837, in get_single_value
    ).run()
      ^^^^^
  File "/home/tridotstech/frappe-training/apps/frappe/frappe/query_builder/utils.py", line 87, in execute_query
    result = frappe.db.sql(query, params, *args, **kwargs)  # nosemgrep
             ^^^^^^^^^^^^^^^^^^^^^^^^^^^^^^^^^^^^^^^^^^^^^
  File "/home/tridotstech/frappe-training/apps/frappe/frappe/database/database.py", line 207, in sql
    self.connect()
  File "/home/tridotstech/frappe-training/apps/frappe/frappe/database/database.py", line 112, in connect
    self._conn: "MariadbConnection" | "PostgresConnection" = self.get_connection()
                                                             ^^^^^^^^^^^^^^^^^^^^^
  File "/home/tridotstech/frappe-training/apps/frappe/frappe/database/mariadb/database.py", line 108, in get_connection
    conn = self._get_connection()
           ^^^^^^^^^^^^^^^^^^^^^^
  File "/home/tridotstech/frappe-training/apps/frappe/frappe/database/mariadb/database.py", line 114, in _get_connection
    return self.create_connection()
           ^^^^^^^^^^^^^^^^^^^^^^^^
  File "/home/tridotstech/frappe-training/apps/frappe/frappe/database/mariadb/database.py", line 117, in create_connection
    return pymysql.connect(**self.get_connection_settings())
           ^^^^^^^^^^^^^^^^^^^^^^^^^^^^^^^^^^^^^^^^^^^^^^^^^
  File "/home/tridotstech/frappe-training/env/lib/python3.11/site-packages/pymysql/connections.py", line 361, in __init__
    self.connect()
  File "/home/tridotstech/frappe-training/env/lib/python3.11/site-packages/pymysql/connections.py", line 716, in connect
    raise exc
pymysql.err.OperationalError: (2003, "Can't connect to MySQL server on '127.0.0.1' ([Errno 111] Connection refused)")
2025-06-28 06:43:17,108 ERROR scheduler Exception in Enqueue Events for Site apple.local
Traceback (most recent call last):
  File "/home/tridotstech/frappe-training/env/lib/python3.11/site-packages/pymysql/connections.py", line 649, in connect
    sock = socket.create_connection(
           ^^^^^^^^^^^^^^^^^^^^^^^^^
  File "/usr/lib/python3.11/socket.py", line 863, in create_connection
    raise exceptions[0]
  File "/usr/lib/python3.11/socket.py", line 848, in create_connection
    sock.connect(sa)
ConnectionRefusedError: [Errno 111] Connection refused

During handling of the above exception, another exception occurred:

Traceback (most recent call last):
  File "/home/tridotstech/frappe-training/apps/frappe/frappe/utils/scheduler.py", line 99, in enqueue_events_for_site
    if is_scheduler_inactive():
       ^^^^^^^^^^^^^^^^^^^^^^^
  File "/home/tridotstech/frappe-training/apps/frappe/frappe/utils/scheduler.py", line 143, in is_scheduler_inactive
    if is_scheduler_disabled(verbose=verbose):
       ^^^^^^^^^^^^^^^^^^^^^^^^^^^^^^^^^^^^^^
  File "/home/tridotstech/frappe-training/apps/frappe/frappe/utils/scheduler.py", line 156, in is_scheduler_disabled
    frappe.db.get_single_value("System Settings", "enable_scheduler")
  File "/home/tridotstech/frappe-training/apps/frappe/frappe/database/database.py", line 837, in get_single_value
    ).run()
      ^^^^^
  File "/home/tridotstech/frappe-training/apps/frappe/frappe/query_builder/utils.py", line 87, in execute_query
    result = frappe.db.sql(query, params, *args, **kwargs)  # nosemgrep
             ^^^^^^^^^^^^^^^^^^^^^^^^^^^^^^^^^^^^^^^^^^^^^
  File "/home/tridotstech/frappe-training/apps/frappe/frappe/database/database.py", line 207, in sql
    self.connect()
  File "/home/tridotstech/frappe-training/apps/frappe/frappe/database/database.py", line 112, in connect
    self._conn: "MariadbConnection" | "PostgresConnection" = self.get_connection()
                                                             ^^^^^^^^^^^^^^^^^^^^^
  File "/home/tridotstech/frappe-training/apps/frappe/frappe/database/mariadb/database.py", line 108, in get_connection
    conn = self._get_connection()
           ^^^^^^^^^^^^^^^^^^^^^^
  File "/home/tridotstech/frappe-training/apps/frappe/frappe/database/mariadb/database.py", line 114, in _get_connection
    return self.create_connection()
           ^^^^^^^^^^^^^^^^^^^^^^^^
  File "/home/tridotstech/frappe-training/apps/frappe/frappe/database/mariadb/database.py", line 117, in create_connection
    return pymysql.connect(**self.get_connection_settings())
           ^^^^^^^^^^^^^^^^^^^^^^^^^^^^^^^^^^^^^^^^^^^^^^^^^
  File "/home/tridotstech/frappe-training/env/lib/python3.11/site-packages/pymysql/connections.py", line 361, in __init__
    self.connect()
  File "/home/tridotstech/frappe-training/env/lib/python3.11/site-packages/pymysql/connections.py", line 716, in connect
    raise exc
pymysql.err.OperationalError: (2003, "Can't connect to MySQL server on '127.0.0.1' ([Errno 111] Connection refused)")
